<?xml version="1.0" ?>
<!-- =================================================================================== -->
<!-- |    This document was autogenerated by xacro from ads_dv.xacro                   | -->
<!-- |    EDITING THIS FILE BY HAND IS NOT RECOMMENDED                                 | -->
<!-- =================================================================================== -->
<sdf version="1.11">
  <model canonical_link="base_link" name="ads_dv">
    <!-- Base Link -->
    <link name="base_link">
      <inertial>
        <!-- Needed to disable lumping -->
        <mass>0.001</mass>
        <inertia>
          <ixx>0.001</ixx>
          <ixy>0</ixy>
          <ixz>0</ixz>
          <iyy>0.001</iyy>
          <iyz>0</iyz>
          <izz>0.001</izz>
        </inertia>
      </inertial>
      <visual name="base_link_visual">
        <geometry>
          <box>
            <size>0.01 0.01 0.01</size>
          </box>
        </geometry>
      </visual>
    </link>
    <!-- Chassis -->
    <link name="chassis">
      <pose relative_to="base_to_chassis">0 0 0 0 0 0</pose>
      <inertial>
        <pose>0 0 0 0 0 0</pose>
        <mass>278</mass>
        <inertia>
          <ixx>14.38</ixx>
          <ixy>0</ixy>
          <ixz>0</ixz>
          <iyy>178.90</iyy>
          <iyz>0</iyz>
          <izz>175.68</izz>
        </inertia>
      </inertial>
      <collision name="chassis_collision">
        <pose>0 0 0 0 0 0</pose>
        <geometry>
          <box>
            <size>2.7 0.489 0.414</size>
          </box>
        </geometry>
      </collision>
      <visual name="chassis_visual">
        <pose>0 0 0 0 0 0</pose>
        <geometry>
          <mesh>
            <uri>model://simulation/models/vehicle/ads-dv.stl</uri>
            <scale>1 1 1</scale>
          </mesh>
        </geometry>
        <material>
          <diffuse>0 0.25 0.1625 1</diffuse>
          <ambient>0 0.25 0.1625 1</ambient>
        </material>
      </visual>
      <sensor name="imu_sensor" type="imu">
        <always_on>1</always_on>
        <update_rate>300</update_rate>
        <visualize>true</visualize>
        <topic>imu</topic>
      </sensor>
    </link>
    <link name="front_left_wheel">
      <pose relative_to="front_left_wheel_joint">0 0 0 0 0 0</pose>
      <inertial>
        <pose>0 0 0 0 0 0</pose>
        <mass>5.5</mass>
        <inertia>
          <ixx>0.11207078795000001</ixx>
          <ixy>0</ixy>
          <ixz>0</ixz>
          <iyy>0.11207078795000001</iyy>
          <iyz>0</iyz>
          <izz>0.1887470134</izz>
        </inertia>
      </inertial>
      <collision name="front_left_wheel_collision">
        <pose>0 0 0 0 0 0</pose>
        <geometry>
          <cylinder>
            <radius>0.2575</radius>
            <length>0.1965</length>
          </cylinder>
        </geometry>
      </collision>
      <visual name="front_left_wheel_visual">
        <pose>0 0 0 0 0 0</pose>
        <geometry>
          <cylinder>
            <radius>0.2575</radius>
            <length>0.1965</length>
          </cylinder>
        </geometry>
        <material>
          <ambient>0 0 0 1</ambient>
          <diffuse>0 0 0 1</diffuse>
        </material>
      </visual>
    </link>
    <joint name="front_left_wheel_joint" type="revolute">
      <pose relative_to="front_left_wheel_steering_link">0 0.09825 0 -1.5707 0 0</pose>
      <parent>front_left_wheel_steering_link</parent>
      <child>front_left_wheel</child>
      <axis>
        <xyz>0 0 1</xyz>
        <limit>
          <lower>-1.79769e+308</lower>
          <upper>1.79769e+308</upper>
          <velocity>10000</velocity>
          <effort>10000</effort>
        </limit>
        <dynamics>
          <spring_reference>0</spring_reference>
          <spring_stiffness>0</spring_stiffness>
        </dynamics>
      </axis>
    </joint>
    <link name="front_right_wheel">
      <pose relative_to="front_right_wheel_joint">0 0 0 0 0 0</pose>
      <inertial>
        <pose>0 0 0 0 0 0</pose>
        <mass>5.5</mass>
        <inertia>
          <ixx>0.11207078795000001</ixx>
          <ixy>0</ixy>
          <ixz>0</ixz>
          <iyy>0.11207078795000001</iyy>
          <iyz>0</iyz>
          <izz>0.1887470134</izz>
        </inertia>
      </inertial>
      <collision name="front_right_wheel_collision">
        <pose>0 0 0 0 0 0</pose>
        <geometry>
          <cylinder>
            <radius>0.2575</radius>
            <length>0.1965</length>
          </cylinder>
        </geometry>
      </collision>
      <visual name="front_right_wheel_visual">
        <pose>0 0 0 0 0 0</pose>
        <geometry>
          <cylinder>
            <radius>0.2575</radius>
            <length>0.1965</length>
          </cylinder>
        </geometry>
        <material>
          <ambient>0 0 0 1</ambient>
          <diffuse>0 0 0 1</diffuse>
        </material>
      </visual>
    </link>
    <joint name="front_right_wheel_joint" type="revolute">
      <pose relative_to="front_right_wheel_steering_link">0 -0.09825 0 -1.5707 0 0</pose>
      <parent>front_right_wheel_steering_link</parent>
      <child>front_right_wheel</child>
      <axis>
        <xyz>0 0 1</xyz>
        <limit>
          <lower>-1.79769e+308</lower>
          <upper>1.79769e+308</upper>
          <velocity>10000</velocity>
          <effort>10000</effort>
        </limit>
        <dynamics>
          <spring_reference>0</spring_reference>
          <spring_stiffness>0</spring_stiffness>
        </dynamics>
      </axis>
    </joint>
    <link name="rear_left_wheel">
      <pose relative_to="rear_left_wheel_joint">0 0 0 0 0 0</pose>
      <inertial>
        <pose>0 0 0 0 0 0</pose>
        <mass>5.5</mass>
        <inertia>
          <ixx>0.11207078795000001</ixx>
          <ixy>0</ixy>
          <ixz>0</ixz>
          <iyy>0.11207078795000001</iyy>
          <iyz>0</iyz>
          <izz>0.1887470134</izz>
        </inertia>
      </inertial>
      <collision name="rear_left_wheel_collision">
        <pose>0 0 0 0 0 0</pose>
        <geometry>
          <cylinder>
            <radius>0.2575</radius>
            <length>0.1965</length>
          </cylinder>
        </geometry>
      </collision>
      <visual name="rear_left_wheel_visual">
        <pose>0 0 0 0 0 0</pose>
        <geometry>
          <cylinder>
            <radius>0.2575</radius>
            <length>0.1965</length>
          </cylinder>
        </geometry>
        <material>
          <ambient>0 0 0 1</ambient>
          <diffuse>0 0 0 1</diffuse>
        </material>
      </visual>
    </link>
    <joint name="rear_left_wheel_joint" type="revolute">
      <pose relative_to="chassis">-0.767 0.57 -0.0235 -1.5707 0 0</pose>
      <parent>chassis</parent>
      <child>rear_left_wheel</child>
      <axis>
        <xyz>0 0 1</xyz>
        <limit>
          <lower>-1.79769e+308</lower>
          <upper>1.79769e+308</upper>
          <velocity>10000</velocity>
          <effort>10000</effort>
        </limit>
        <dynamics>
          <spring_reference>0</spring_reference>
          <spring_stiffness>0</spring_stiffness>
        </dynamics>
      </axis>
    </joint>
    <link name="rear_right_wheel">
      <pose relative_to="rear_right_wheel_joint">0 0 0 0 0 0</pose>
      <inertial>
        <pose>0 0 0 0 0 0</pose>
        <mass>5.5</mass>
        <inertia>
          <ixx>0.11207078795000001</ixx>
          <ixy>0</ixy>
          <ixz>0</ixz>
          <iyy>0.11207078795000001</iyy>
          <iyz>0</iyz>
          <izz>0.1887470134</izz>
        </inertia>
      </inertial>
      <collision name="rear_right_wheel_collision">
        <pose>0 0 0 0 0 0</pose>
        <geometry>
          <cylinder>
            <radius>0.2575</radius>
            <length>0.1965</length>
          </cylinder>
        </geometry>
      </collision>
      <visual name="rear_right_wheel_visual">
        <pose>0 0 0 0 0 0</pose>
        <geometry>
          <cylinder>
            <radius>0.2575</radius>
            <length>0.1965</length>
          </cylinder>
        </geometry>
        <material>
          <ambient>0 0 0 1</ambient>
          <diffuse>0 0 0 1</diffuse>
        </material>
      </visual>
    </link>
    <joint name="rear_right_wheel_joint" type="revolute">
      <pose relative_to="chassis">-0.767 -0.57 -0.0235 -1.5707 0 0</pose>
      <parent>chassis</parent>
      <child>rear_right_wheel</child>
      <axis>
        <xyz>0 0 1</xyz>
        <limit>
          <lower>-1.79769e+308</lower>
          <upper>1.79769e+308</upper>
          <velocity>10000</velocity>
          <effort>10000</effort>
        </limit>
        <dynamics>
          <spring_reference>0</spring_reference>
          <spring_stiffness>0</spring_stiffness>
        </dynamics>
      </axis>
    </joint>
    <link name="front_left_wheel_steering_link">
      <pose relative_to="front_left_wheel_steering_joint">0 0 0 0 0 0</pose>
      <inertial>
        <pose>0 0 0 0 0 0</pose>
        <mass>0.001</mass>
        <inertia>
          <ixx>0.001</ixx>
          <ixy>0</ixy>
          <ixz>0</ixz>
          <iyy>0.001</iyy>
          <iyz>0</iyz>
          <izz>0.001</izz>
        </inertia>
      </inertial>
      <visual name="front_left_wheel_steering_link_visual">
        <pose>0 0 0 0 0 0</pose>
        <geometry>
          <cylinder>
            <radius>0.03</radius>
            <length>0.1</length>
          </cylinder>
        </geometry>
      </visual>
    </link>
    <joint name="front_left_wheel_steering_joint" type="revolute">
      <pose relative_to="chassis">0.767 0.47175 -0.0235 0 0 0</pose>
      <parent>chassis</parent>
      <child>front_left_wheel_steering_link</child>
      <axis>
        <xyz>0 0 1</xyz>
        <limit>
          <lower>-0.424250477138</lower>
          <upper>0.424250477138</upper>
          <velocity>10000</velocity>
          <effort>10000</effort>
        </limit>
        <dynamics>
          <spring_reference>0</spring_reference>
          <spring_stiffness>0</spring_stiffness>
        </dynamics>
      </axis>
    </joint>
    <link name="front_right_wheel_steering_link">
      <pose relative_to="front_right_wheel_steering_joint">0 0 0 0 0 0</pose>
      <inertial>
        <pose>0 0 0 0 0 0</pose>
        <mass>0.001</mass>
        <inertia>
          <ixx>0.001</ixx>
          <ixy>0</ixy>
          <ixz>0</ixz>
          <iyy>0.001</iyy>
          <iyz>0</iyz>
          <izz>0.001</izz>
        </inertia>
      </inertial>
      <visual name="front_right_wheel_steering_link_visual">
        <pose>0 0 0 0 0 0</pose>
        <geometry>
          <cylinder>
            <radius>0.03</radius>
            <length>0.1</length>
          </cylinder>
        </geometry>
      </visual>
    </link>
    <joint name="front_right_wheel_steering_joint" type="revolute">
      <pose relative_to="chassis">0.767 -0.47175 -0.0235 0 0 0</pose>
      <parent>chassis</parent>
      <child>front_right_wheel_steering_link</child>
      <axis>
        <xyz>0 0 1</xyz>
        <limit>
          <lower>-0.424250477138</lower>
          <upper>0.424250477138</upper>
          <velocity>10000</velocity>
          <effort>10000</effort>
        </limit>
        <dynamics>
          <spring_reference>0</spring_reference>
          <spring_stiffness>0</spring_stiffness>
        </dynamics>
      </axis>
    </joint>
    <!-- Fixed Joints -->
    <joint name="base_to_camera" type="fixed">
      <pose relative_to="base_link">0.4865 0 0.671 0 0 0</pose>
      <parent>base_link</parent>
      <child>camera_link</child>
    </joint>
    <joint name="base_to_logical_camera" type="fixed">
      <pose relative_to="base_link">0.4865 0 0.671 0 0 0</pose>
      <parent>base_link</parent>
      <child>logical_camera_link</child>
    </joint>
    <joint name="base_to_velodyne" type="fixed">
      <pose relative_to="base_link">0.52 0 0.59946 0 0 0</pose>
      <parent>base_link</parent>
      <child>velodyne</child>
    </joint>
    <joint name="base_to_chassis" type="fixed">
      <pose relative_to="base_link">0 0 0.307 0 0 0</pose>
      <parent>base_link</parent>
      <child>chassis</child>
    </joint>
    <!-- Depth Camera -->
    <link name="camera_link">
      <pose relative_to="base_to_camera">0 0 0 0 0 0</pose>
      <inertial>
        <mass>0.001</mass>
        <inertia>
          <ixx>0.001</ixx>
          <ixy>0</ixy>
          <ixz>0</ixz>
          <iyy>0.001</iyy>
          <iyz>0</iyz>
          <izz>0.001</izz>
        </inertia>
      </inertial>
      <visual name="camera_link_visual">
        <geometry>
          <box>
            <size>0.0431 0.17525 0.03025</size>
          </box>
        </geometry>
      </visual>
    </link>
    <link name="camera_link_optical">
      <pose relative_to="camera_to_optical">0 0 0 0 0 0</pose>
      <inertial>
        <mass>0.001</mass>
        <inertia>
          <ixx>0.001</ixx>
          <ixy>0</ixy>
          <ixz>0</ixz>
          <iyy>0.001</iyy>
          <iyz>0</iyz>
          <izz>0.001</izz>
        </inertia>
      </inertial>
      <sensor name="zed2i_depth_camera" type="rgbd_camera">
        <gz_frame_id>camera_link_optical</gz_frame_id>
        <update_rate>30</update_rate>
        <topic>zed2i/depth_camera</topic>
        <camera>
          <camera_info_topic>camera_info</camera_info_topic>
          <horizontal_fov>1.22173</horizontal_fov>
          <image>
            <width>640</width>
            <height>480</height>
            <format>R_FLOAT32</format>
          </image>
          <clip>
            <near>1.5</near>
            <far>35.0</far>
          </clip>
          <noise>
            <!-- This is an unrealistic depth noise model, but that's what's available currently -->
            <!-- Probably a good idea to simulate a stereo camera and use a ROS node to estimate depth -->
            <!-- Or ditch Gazebo altogether -->
            <type>gaussian</type>
            <mean>0.0</mean>
            <stddev>0.007</stddev>
          </noise>
          <distortion>
            <k1>0.0</k1>
            <k2>0.0</k2>
            <k3>0.0</k3>
            <p1>0.0</p1>
            <p2>0.0</p2>
          </distortion>
        </camera>
      </sensor>
    </link>
    <joint name="camera_to_optical" type="fixed">
      <pose relative_to="camera_link">0 0 0 0 0 0</pose>
      <parent>camera_link</parent>
      <child>camera_link_optical</child>
    </joint>
    <!-- Logical Camera -->
    <link name="logical_camera_link">
      <pose relative_to="base_to_logical_camera">0 0 0 0 0 0</pose>
      <inertial>
        <mass>0.001</mass>
        <inertia>
          <ixx>0.001</ixx>
          <ixy>0</ixy>
          <ixz>0</ixz>
          <iyy>0.001</iyy>
          <iyz>0</iyz>
          <izz>0.001</izz>
        </inertia>
      </inertial>
      <sensor name="logical_camera" type="logical_camera">
        <gz_frame_id>camera_link_optical</gz_frame_id>
        <update_rate>30</update_rate>
        <topic>logical_camera</topic>
        <always_on>true</always_on>
        <visualize>true</visualize>
        <enable_metrics>true</enable_metrics>
        <logical_camera>
          <near>1.5</near>
          <far>35</far>
          <aspect_ratio>1.333333333333333</aspect_ratio>
          <horizontal_fov>1.22173</horizontal_fov>
        </logical_camera>
      </sensor>
    </link>
    <!-- Velodyne -->
    <link name="velodyne">
      <pose relative_to="base_to_velodyne">0 0 0 0 0 0</pose>
      <inertial>
        <pose>0 0 0 0 0 0</pose>
        <mass>0.001</mass>
        <inertia>
          <ixx>0.001</ixx>
          <ixy>0</ixy>
          <ixz>0</ixz>
          <iyy>0.001</iyy>
          <iyz>0</iyz>
          <izz>0.001</izz>
        </inertia>
      </inertial>
      <visual name="velodyne_visual">
        <pose>0 0 0 0 0 0</pose>
        <geometry>
          <cylinder>
            <radius>0.05</radius>
            <length>0.07</length>
          </cylinder>
        </geometry>
      </visual>
      <sensor name="VLP-16" type="gpu_lidar">
        <gz_frame_id>velodyne</gz_frame_id>
        <!-- Change to frame_id when sdformat_urdf's parser supports sdf spec 1.12 -->
        <topic>velodyne</topic>
        <update_rate>10</update_rate>
        <ray>
          <scan>
            <horizontal>
              <samples>1800</samples>
              <resolution>0.003490659</resolution>
              <!-- 0.2 degrees -->
              <min_angle>-0.785398</min_angle>
              <max_angle>0.785398</max_angle>
            </horizontal>
            <vertical>
              <samples>16</samples>
              <resolution>0.034906585</resolution>
              <min_angle>-0.26179938</min_angle>
              <max_angle>0.26179939</max_angle>
            </vertical>
          </scan>
          <range>
            <min>1.5</min>
            <max>100.0</max>
            <resolution>0.002</resolution>
          </range>
        </ray>
        <always_on>1</always_on>
        <visualize>true</visualize>
      </sensor>
    </link>
    <!-- Ackermann Steering Plugin -->
    <plugin filename="gz-sim-ackermann-steering-system" name="gz::sim::systems::AckermannSteering">
      <steering_only>True</steering_only>
      <steer_p_gain>5.0</steer_p_gain>
      <left_joint>front_left_wheel_joint</left_joint>
      <left_joint>rear_left_wheel_joint</left_joint>
      <right_joint>front_right_wheel_joint</right_joint>
      <right_joint>rear_right_wheel_joint</right_joint>
      <left_steering_joint>front_left_wheel_steering_joint</left_steering_joint>
      <right_steering_joint>front_right_wheel_steering_joint</right_steering_joint>
      <kingpin_width>1.0</kingpin_width>
      <!-- or 0.72 idk maybe change it later and see how it affects the simulation -->
      <steering_limit>0.424250477138</steering_limit>
      <wheel_base>1.534</wheel_base>
      <wheel_separation>1.2</wheel_separation>
      <wheel_radius>0.2575</wheel_radius>
      <topic>steer_angle_cmd</topic>
      <odom_publish_frequency>50</odom_publish_frequency>
      <!-- Don't use that anymore-->
      <min_velocity>-10.0</min_velocity>
      <!-- the plugin currently prevents steering to the right if this is set to 0 -->
      <max_velocity>30.0</max_velocity>
      <min_acceleration>-5.2</min_acceleration>
      <max_acceleration>5.2</max_acceleration>
      <frame_id>odom</frame_id>
      <child_frame_id>base_link</child_frame_id>
    </plugin>
    <plugin filename="gz-sim-joint-controller-system" name="gz::sim::systems::JointController">
      <joint_name>rear_left_wheel_joint</joint_name>
      <joint_name>rear_right_wheel_joint</joint_name>
      <topic>speed_cmd</topic>
    </plugin>
    <plugin filename="gz-sim-logical-camera-system" name="gz::sim::systems::LogicalCamera">
      <render_engine>ogre2</render_engine>
    </plugin>
    <plugin filename="gz-sim-joint-state-publisher-system" name="gz::sim::systems::JointStatePublisher">
      <topic>/model/ads_dv/joint_state</topic>
    </plugin>
    <plugin filename="gz-sim-imu-system" name="gz::sim::systems::Imu">
        </plugin>
    <plugin filename="gz-sim-odometry-publisher-system" name="gz::sim::systems::OdometryPublisher">
      <odom_frame>odom</odom_frame>
      <robot_base_frame>base_link</robot_base_frame>
      <odom_publish_frequency>600</odom_publish_frequency>
      <odom_topic>ads_dv/odom</odom_topic>
      <tf_topic>ads_dv/tf</tf_topic>
      <!-- not the same as /model/ads_dv/tf or model/ads_dv/odom which AckermannSteering publishes. Don't use that, it depends on the wheel joints and not the actual location -->
    </plugin>
  </model>
</sdf>
